[2025-03-30T11:11:32.739+0000] {taskinstance.py:1979} INFO - Dependencies all met for dep_context=non-requeueable deps ti=<TaskInstance: inout_data_ingestion.ingest_dummy_data scheduled__2024-10-04T01:30:00+00:00 [queued]>
[2025-03-30T11:11:32.747+0000] {taskinstance.py:1979} INFO - Dependencies all met for dep_context=requeueable deps ti=<TaskInstance: inout_data_ingestion.ingest_dummy_data scheduled__2024-10-04T01:30:00+00:00 [queued]>
[2025-03-30T11:11:32.748+0000] {taskinstance.py:2193} INFO - Starting attempt 1 of 2
[2025-03-30T11:11:32.758+0000] {taskinstance.py:2214} INFO - Executing <Task(PythonOperator): ingest_dummy_data> on 2024-10-04 01:30:00+00:00
[2025-03-30T11:11:32.761+0000] {standard_task_runner.py:60} INFO - Started process 1073 to run task
[2025-03-30T11:11:32.763+0000] {standard_task_runner.py:87} INFO - Running: ['***', 'tasks', 'run', 'inout_data_ingestion', 'ingest_dummy_data', 'scheduled__2024-10-04T01:30:00+00:00', '--job-id', '511', '--raw', '--subdir', 'DAGS_FOLDER/inout_data.py', '--cfg-path', '/tmp/tmplws3g7md']
[2025-03-30T11:11:32.765+0000] {standard_task_runner.py:88} INFO - Job 511: Subtask ingest_dummy_data
[2025-03-30T11:11:32.774+0000] {warnings.py:109} WARNING - /home/***/.local/lib/python3.8/site-packages/***/settings.py:194: DeprecationWarning: The sql_alchemy_conn option in [core] has been moved to the sql_alchemy_conn option in [database] - the old setting has been used, but please update your config.
  SQL_ALCHEMY_CONN = conf.get("database", "SQL_ALCHEMY_CONN")

[2025-03-30T11:11:32.795+0000] {task_command.py:423} INFO - Running <TaskInstance: inout_data_ingestion.ingest_dummy_data scheduled__2024-10-04T01:30:00+00:00 [running]> on host ff9d64b065e6
[2025-03-30T11:11:32.839+0000] {taskinstance.py:2510} INFO - Exporting env vars: AIRFLOW_CTX_DAG_OWNER='***' AIRFLOW_CTX_DAG_ID='inout_data_ingestion' AIRFLOW_CTX_TASK_ID='ingest_dummy_data' AIRFLOW_CTX_EXECUTION_DATE='2024-10-04T01:30:00+00:00' AIRFLOW_CTX_TRY_NUMBER='1' AIRFLOW_CTX_DAG_RUN_ID='scheduled__2024-10-04T01:30:00+00:00'
[2025-03-30T11:11:32.841+0000] {inout_data.py:42} INFO - Successfully connected to MariaDB: INOUT on mariadb:3306
[2025-03-30T11:11:32.842+0000] {inout_data.py:63} ERROR - Error executing query: (1062, "Duplicate entry '2025-03-30 11:11:32-9947' for key 'PRIMARY'")
[2025-03-30T11:11:32.842+0000] {inout_data.py:63} ERROR - Error executing query: (1062, "Duplicate entry '2025-03-30 11:11:32-9947' for key 'PRIMARY'")
[2025-03-30T11:11:32.843+0000] {inout_data.py:63} ERROR - Error executing query: (1062, "Duplicate entry '2025-03-30 11:11:32-9947' for key 'PRIMARY'")
[2025-03-30T11:11:32.843+0000] {inout_data.py:63} ERROR - Error executing query: (1062, "Duplicate entry '2025-03-30 11:11:32-9947' for key 'PRIMARY'")
[2025-03-30T11:11:32.843+0000] {inout_data.py:63} ERROR - Error executing query: (1062, "Duplicate entry '2025-03-30 11:11:32-9947' for key 'PRIMARY'")
[2025-03-30T11:11:32.844+0000] {inout_data.py:63} ERROR - Error executing query: (1062, "Duplicate entry '2025-03-30 11:11:32-9947' for key 'PRIMARY'")
[2025-03-30T11:11:32.845+0000] {inout_data.py:63} ERROR - Error executing query: (1062, "Duplicate entry '2025-03-30 11:11:32-9947' for key 'PRIMARY'")
[2025-03-30T11:11:32.846+0000] {inout_data.py:63} ERROR - Error executing query: (1062, "Duplicate entry '2025-03-30 11:11:32-9947' for key 'PRIMARY'")
[2025-03-30T11:11:32.846+0000] {inout_data.py:63} ERROR - Error executing query: (1062, "Duplicate entry '2025-03-30 11:11:32-9947' for key 'PRIMARY'")
[2025-03-30T11:11:32.847+0000] {inout_data.py:63} ERROR - Error executing query: (1062, "Duplicate entry '2025-03-30 11:11:32-9947' for key 'PRIMARY'")
[2025-03-30T11:11:32.847+0000] {inout_data.py:63} ERROR - Error executing query: (1062, "Duplicate entry '2025-03-30 11:11:32-9947' for key 'PRIMARY'")
[2025-03-30T11:11:32.848+0000] {inout_data.py:63} ERROR - Error executing query: (1062, "Duplicate entry '2025-03-30 11:11:32-9947' for key 'PRIMARY'")
[2025-03-30T11:11:32.848+0000] {inout_data.py:63} ERROR - Error executing query: (1062, "Duplicate entry '2025-03-30 11:11:32-9947' for key 'PRIMARY'")
[2025-03-30T11:11:32.848+0000] {inout_data.py:63} ERROR - Error executing query: (1062, "Duplicate entry '2025-03-30 11:11:32-9947' for key 'PRIMARY'")
[2025-03-30T11:11:32.849+0000] {inout_data.py:63} ERROR - Error executing query: (1062, "Duplicate entry '2025-03-30 11:11:32-9947' for key 'PRIMARY'")
[2025-03-30T11:11:32.849+0000] {inout_data.py:63} ERROR - Error executing query: (1062, "Duplicate entry '2025-03-30 11:11:32-9947' for key 'PRIMARY'")
[2025-03-30T11:11:32.849+0000] {inout_data.py:63} ERROR - Error executing query: (1062, "Duplicate entry '2025-03-30 11:11:32-9947' for key 'PRIMARY'")
[2025-03-30T11:11:32.849+0000] {inout_data.py:63} ERROR - Error executing query: (1062, "Duplicate entry '2025-03-30 11:11:32-9947' for key 'PRIMARY'")
[2025-03-30T11:11:32.850+0000] {inout_data.py:159} INFO - Ingested 19 rows of dummy data.
[2025-03-30T11:11:32.850+0000] {inout_data.py:78} INFO - MariaDB connection closed.
[2025-03-30T11:11:32.850+0000] {python.py:202} INFO - Done. Returned value was: None
[2025-03-30T11:11:32.854+0000] {taskinstance.py:1149} INFO - Marking task as SUCCESS. dag_id=inout_data_ingestion, task_id=ingest_dummy_data, execution_date=20241004T013000, start_date=20250330T111132, end_date=20250330T111132
[2025-03-30T11:11:32.903+0000] {local_task_job_runner.py:234} INFO - Task exited with return code 0
[2025-03-30T11:11:32.910+0000] {taskinstance.py:3309} INFO - 0 downstream tasks scheduled from follow-on schedule check
[2025-03-30T11:18:05.980+0000] {taskinstance.py:1979} INFO - Dependencies all met for dep_context=non-requeueable deps ti=<TaskInstance: inout_data_ingestion.ingest_dummy_data scheduled__2024-10-04T01:30:00+00:00 [queued]>
[2025-03-30T11:18:05.988+0000] {taskinstance.py:1979} INFO - Dependencies all met for dep_context=requeueable deps ti=<TaskInstance: inout_data_ingestion.ingest_dummy_data scheduled__2024-10-04T01:30:00+00:00 [queued]>
[2025-03-30T11:18:05.988+0000] {taskinstance.py:2193} INFO - Starting attempt 1 of 2
[2025-03-30T11:18:06.005+0000] {taskinstance.py:2214} INFO - Executing <Task(PythonOperator): ingest_dummy_data> on 2024-10-04 01:30:00+00:00
[2025-03-30T11:18:06.010+0000] {standard_task_runner.py:60} INFO - Started process 2932 to run task
[2025-03-30T11:18:06.015+0000] {standard_task_runner.py:87} INFO - Running: ['***', 'tasks', 'run', 'inout_data_ingestion', 'ingest_dummy_data', 'scheduled__2024-10-04T01:30:00+00:00', '--job-id', '1441', '--raw', '--subdir', 'DAGS_FOLDER/inout_data.py', '--cfg-path', '/tmp/tmp_7v0yino']
[2025-03-30T11:18:06.016+0000] {standard_task_runner.py:88} INFO - Job 1441: Subtask ingest_dummy_data
[2025-03-30T11:18:06.033+0000] {warnings.py:109} WARNING - /home/***/.local/lib/python3.8/site-packages/***/settings.py:194: DeprecationWarning: The sql_alchemy_conn option in [core] has been moved to the sql_alchemy_conn option in [database] - the old setting has been used, but please update your config.
  SQL_ALCHEMY_CONN = conf.get("database", "SQL_ALCHEMY_CONN")

[2025-03-30T11:18:06.064+0000] {task_command.py:423} INFO - Running <TaskInstance: inout_data_ingestion.ingest_dummy_data scheduled__2024-10-04T01:30:00+00:00 [running]> on host ff9d64b065e6
[2025-03-30T11:18:06.130+0000] {taskinstance.py:2510} INFO - Exporting env vars: AIRFLOW_CTX_DAG_OWNER='***' AIRFLOW_CTX_DAG_ID='inout_data_ingestion' AIRFLOW_CTX_TASK_ID='ingest_dummy_data' AIRFLOW_CTX_EXECUTION_DATE='2024-10-04T01:30:00+00:00' AIRFLOW_CTX_TRY_NUMBER='1' AIRFLOW_CTX_DAG_RUN_ID='scheduled__2024-10-04T01:30:00+00:00'
[2025-03-30T11:18:06.137+0000] {inout_data.py:42} INFO - Successfully connected to MariaDB: INOUT on mariadb:3306
[2025-03-30T11:18:06.139+0000] {inout_data.py:63} ERROR - Error executing query: (1062, "Duplicate entry '2025-03-30 11:18:06-3472' for key 'PRIMARY'")
[2025-03-30T11:18:06.140+0000] {inout_data.py:63} ERROR - Error executing query: (1062, "Duplicate entry '2025-03-30 11:18:06-3472' for key 'PRIMARY'")
[2025-03-30T11:18:06.141+0000] {inout_data.py:63} ERROR - Error executing query: (1062, "Duplicate entry '2025-03-30 11:18:06-3472' for key 'PRIMARY'")
[2025-03-30T11:18:06.142+0000] {inout_data.py:63} ERROR - Error executing query: (1062, "Duplicate entry '2025-03-30 11:18:06-3472' for key 'PRIMARY'")
[2025-03-30T11:18:06.143+0000] {inout_data.py:63} ERROR - Error executing query: (1062, "Duplicate entry '2025-03-30 11:18:06-3472' for key 'PRIMARY'")
[2025-03-30T11:18:06.144+0000] {inout_data.py:63} ERROR - Error executing query: (1062, "Duplicate entry '2025-03-30 11:18:06-3472' for key 'PRIMARY'")
[2025-03-30T11:18:06.145+0000] {inout_data.py:63} ERROR - Error executing query: (1062, "Duplicate entry '2025-03-30 11:18:06-3472' for key 'PRIMARY'")
[2025-03-30T11:18:06.146+0000] {inout_data.py:63} ERROR - Error executing query: (1062, "Duplicate entry '2025-03-30 11:18:06-3472' for key 'PRIMARY'")
[2025-03-30T11:18:06.147+0000] {inout_data.py:63} ERROR - Error executing query: (1062, "Duplicate entry '2025-03-30 11:18:06-3472' for key 'PRIMARY'")
[2025-03-30T11:18:06.148+0000] {inout_data.py:63} ERROR - Error executing query: (1062, "Duplicate entry '2025-03-30 11:18:06-3472' for key 'PRIMARY'")
[2025-03-30T11:18:06.149+0000] {inout_data.py:63} ERROR - Error executing query: (1062, "Duplicate entry '2025-03-30 11:18:06-3472' for key 'PRIMARY'")
[2025-03-30T11:18:06.149+0000] {inout_data.py:152} INFO - Ingested 12 rows of dummy data.
[2025-03-30T11:18:06.150+0000] {inout_data.py:78} INFO - MariaDB connection closed.
[2025-03-30T11:18:06.150+0000] {python.py:202} INFO - Done. Returned value was: None
[2025-03-30T11:18:06.158+0000] {taskinstance.py:1149} INFO - Marking task as SUCCESS. dag_id=inout_data_ingestion, task_id=ingest_dummy_data, execution_date=20241004T013000, start_date=20250330T111805, end_date=20250330T111806
[2025-03-30T11:18:06.195+0000] {local_task_job_runner.py:234} INFO - Task exited with return code 0
[2025-03-30T11:18:06.213+0000] {taskinstance.py:3309} INFO - 0 downstream tasks scheduled from follow-on schedule check
[2025-03-30T11:30:28.764+0000] {taskinstance.py:1979} INFO - Dependencies all met for dep_context=non-requeueable deps ti=<TaskInstance: inout_data_ingestion.ingest_dummy_data scheduled__2024-10-04T01:30:00+00:00 [queued]>
[2025-03-30T11:30:28.780+0000] {taskinstance.py:1979} INFO - Dependencies all met for dep_context=requeueable deps ti=<TaskInstance: inout_data_ingestion.ingest_dummy_data scheduled__2024-10-04T01:30:00+00:00 [queued]>
[2025-03-30T11:30:28.781+0000] {taskinstance.py:2193} INFO - Starting attempt 1 of 2
[2025-03-30T11:30:28.808+0000] {taskinstance.py:2214} INFO - Executing <Task(PythonOperator): ingest_dummy_data> on 2024-10-04 01:30:00+00:00
[2025-03-30T11:30:28.814+0000] {standard_task_runner.py:60} INFO - Started process 4858 to run task
[2025-03-30T11:30:28.819+0000] {standard_task_runner.py:87} INFO - Running: ['***', 'tasks', 'run', 'inout_data_ingestion', 'ingest_dummy_data', 'scheduled__2024-10-04T01:30:00+00:00', '--job-id', '2403', '--raw', '--subdir', 'DAGS_FOLDER/inout_data.py', '--cfg-path', '/tmp/tmpo8k9yzm8']
[2025-03-30T11:30:28.821+0000] {standard_task_runner.py:88} INFO - Job 2403: Subtask ingest_dummy_data
[2025-03-30T11:30:28.845+0000] {warnings.py:109} WARNING - /home/***/.local/lib/python3.8/site-packages/***/settings.py:194: DeprecationWarning: The sql_alchemy_conn option in [core] has been moved to the sql_alchemy_conn option in [database] - the old setting has been used, but please update your config.
  SQL_ALCHEMY_CONN = conf.get("database", "SQL_ALCHEMY_CONN")

[2025-03-30T11:30:28.883+0000] {task_command.py:423} INFO - Running <TaskInstance: inout_data_ingestion.ingest_dummy_data scheduled__2024-10-04T01:30:00+00:00 [running]> on host ff9d64b065e6
[2025-03-30T11:30:28.964+0000] {taskinstance.py:2510} INFO - Exporting env vars: AIRFLOW_CTX_DAG_OWNER='***' AIRFLOW_CTX_DAG_ID='inout_data_ingestion' AIRFLOW_CTX_TASK_ID='ingest_dummy_data' AIRFLOW_CTX_EXECUTION_DATE='2024-10-04T01:30:00+00:00' AIRFLOW_CTX_TRY_NUMBER='1' AIRFLOW_CTX_DAG_RUN_ID='scheduled__2024-10-04T01:30:00+00:00'
[2025-03-30T11:30:28.968+0000] {logging_mixin.py:188} INFO - Successfully connected to MariaDB: INOUT on mariadb:3306
[2025-03-30T11:30:28.969+0000] {logging_mixin.py:188} INFO - General error executing query: not all arguments converted during string formatting
[2025-03-30T11:30:28.970+0000] {logging_mixin.py:188} INFO - General error executing query: not all arguments converted during string formatting
[2025-03-30T11:30:28.970+0000] {logging_mixin.py:188} INFO - General error executing query: not all arguments converted during string formatting
[2025-03-30T11:30:28.971+0000] {logging_mixin.py:188} INFO - General error executing query: not all arguments converted during string formatting
[2025-03-30T11:30:28.972+0000] {logging_mixin.py:188} INFO - General error executing query: not all arguments converted during string formatting
[2025-03-30T11:30:28.973+0000] {logging_mixin.py:188} INFO - General error executing query: not all arguments converted during string formatting
[2025-03-30T11:30:28.974+0000] {logging_mixin.py:188} INFO - General error executing query: not all arguments converted during string formatting
[2025-03-30T11:30:28.974+0000] {inout_data.py:87} INFO - Ingested 7 rows of dummy data for 2024-10-04 01:30:00+00:00.
[2025-03-30T11:30:28.975+0000] {logging_mixin.py:188} INFO - MariaDB connection closed.
[2025-03-30T11:30:28.976+0000] {python.py:202} INFO - Done. Returned value was: None
[2025-03-30T11:30:28.986+0000] {taskinstance.py:1149} INFO - Marking task as SUCCESS. dag_id=inout_data_ingestion, task_id=ingest_dummy_data, execution_date=20241004T013000, start_date=20250330T113028, end_date=20250330T113028
[2025-03-30T11:30:29.043+0000] {local_task_job_runner.py:234} INFO - Task exited with return code 0
[2025-03-30T11:30:29.072+0000] {taskinstance.py:3309} INFO - 0 downstream tasks scheduled from follow-on schedule check
