[2025-03-30T11:13:15.280+0000] {taskinstance.py:1979} INFO - Dependencies all met for dep_context=non-requeueable deps ti=<TaskInstance: inout_data_ingestion.ingest_dummy_data scheduled__2024-10-07T03:00:00+00:00 [queued]>
[2025-03-30T11:13:15.305+0000] {taskinstance.py:1979} INFO - Dependencies all met for dep_context=requeueable deps ti=<TaskInstance: inout_data_ingestion.ingest_dummy_data scheduled__2024-10-07T03:00:00+00:00 [queued]>
[2025-03-30T11:13:15.306+0000] {taskinstance.py:2193} INFO - Starting attempt 1 of 2
[2025-03-30T11:13:15.329+0000] {taskinstance.py:2214} INFO - Executing <Task(PythonOperator): ingest_dummy_data> on 2024-10-07 03:00:00+00:00
[2025-03-30T11:13:15.338+0000] {standard_task_runner.py:60} INFO - Started process 1670 to run task
[2025-03-30T11:13:15.345+0000] {standard_task_runner.py:87} INFO - Running: ['***', 'tasks', 'run', 'inout_data_ingestion', 'ingest_dummy_data', 'scheduled__2024-10-07T03:00:00+00:00', '--job-id', '809', '--raw', '--subdir', 'DAGS_FOLDER/inout_data.py', '--cfg-path', '/tmp/tmpnp_5rhnh']
[2025-03-30T11:13:15.353+0000] {standard_task_runner.py:88} INFO - Job 809: Subtask ingest_dummy_data
[2025-03-30T11:13:15.372+0000] {warnings.py:109} WARNING - /home/***/.local/lib/python3.8/site-packages/***/settings.py:194: DeprecationWarning: The sql_alchemy_conn option in [core] has been moved to the sql_alchemy_conn option in [database] - the old setting has been used, but please update your config.
  SQL_ALCHEMY_CONN = conf.get("database", "SQL_ALCHEMY_CONN")

[2025-03-30T11:13:15.422+0000] {task_command.py:423} INFO - Running <TaskInstance: inout_data_ingestion.ingest_dummy_data scheduled__2024-10-07T03:00:00+00:00 [running]> on host ff9d64b065e6
[2025-03-30T11:13:15.569+0000] {taskinstance.py:2510} INFO - Exporting env vars: AIRFLOW_CTX_DAG_OWNER='***' AIRFLOW_CTX_DAG_ID='inout_data_ingestion' AIRFLOW_CTX_TASK_ID='ingest_dummy_data' AIRFLOW_CTX_EXECUTION_DATE='2024-10-07T03:00:00+00:00' AIRFLOW_CTX_TRY_NUMBER='1' AIRFLOW_CTX_DAG_RUN_ID='scheduled__2024-10-07T03:00:00+00:00'
[2025-03-30T11:13:15.578+0000] {inout_data.py:42} INFO - Successfully connected to MariaDB: INOUT on mariadb:3306
[2025-03-30T11:13:15.581+0000] {inout_data.py:63} ERROR - Error executing query: (1062, "Duplicate entry '2025-03-30 11:13:15-3604' for key 'PRIMARY'")
[2025-03-30T11:13:15.581+0000] {inout_data.py:63} ERROR - Error executing query: (1062, "Duplicate entry '2025-03-30 11:13:15-3604' for key 'PRIMARY'")
[2025-03-30T11:13:15.585+0000] {inout_data.py:63} ERROR - Error executing query: (1062, "Duplicate entry '2025-03-30 11:13:15-3604' for key 'PRIMARY'")
[2025-03-30T11:13:15.590+0000] {inout_data.py:63} ERROR - Error executing query: (1062, "Duplicate entry '2025-03-30 11:13:15-3604' for key 'PRIMARY'")
[2025-03-30T11:13:15.591+0000] {inout_data.py:159} INFO - Ingested 5 rows of dummy data.
[2025-03-30T11:13:15.592+0000] {inout_data.py:78} INFO - MariaDB connection closed.
[2025-03-30T11:13:15.594+0000] {python.py:202} INFO - Done. Returned value was: None
[2025-03-30T11:13:15.618+0000] {taskinstance.py:1149} INFO - Marking task as SUCCESS. dag_id=inout_data_ingestion, task_id=ingest_dummy_data, execution_date=20241007T030000, start_date=20250330T111315, end_date=20250330T111315
[2025-03-30T11:13:15.692+0000] {local_task_job_runner.py:234} INFO - Task exited with return code 0
[2025-03-30T11:13:15.733+0000] {taskinstance.py:3309} INFO - 0 downstream tasks scheduled from follow-on schedule check
[2025-03-30T11:19:55.638+0000] {taskinstance.py:1979} INFO - Dependencies all met for dep_context=non-requeueable deps ti=<TaskInstance: inout_data_ingestion.ingest_dummy_data scheduled__2024-10-07T03:00:00+00:00 [queued]>
[2025-03-30T11:19:55.646+0000] {taskinstance.py:1979} INFO - Dependencies all met for dep_context=requeueable deps ti=<TaskInstance: inout_data_ingestion.ingest_dummy_data scheduled__2024-10-07T03:00:00+00:00 [queued]>
[2025-03-30T11:19:55.647+0000] {taskinstance.py:2193} INFO - Starting attempt 1 of 2
[2025-03-30T11:19:55.659+0000] {taskinstance.py:2214} INFO - Executing <Task(PythonOperator): ingest_dummy_data> on 2024-10-07 03:00:00+00:00
[2025-03-30T11:19:55.662+0000] {standard_task_runner.py:60} INFO - Started process 3515 to run task
[2025-03-30T11:19:55.665+0000] {standard_task_runner.py:87} INFO - Running: ['***', 'tasks', 'run', 'inout_data_ingestion', 'ingest_dummy_data', 'scheduled__2024-10-07T03:00:00+00:00', '--job-id', '1733', '--raw', '--subdir', 'DAGS_FOLDER/inout_data.py', '--cfg-path', '/tmp/tmp2zwwvy47']
[2025-03-30T11:19:55.666+0000] {standard_task_runner.py:88} INFO - Job 1733: Subtask ingest_dummy_data
[2025-03-30T11:19:55.673+0000] {warnings.py:109} WARNING - /home/***/.local/lib/python3.8/site-packages/***/settings.py:194: DeprecationWarning: The sql_alchemy_conn option in [core] has been moved to the sql_alchemy_conn option in [database] - the old setting has been used, but please update your config.
  SQL_ALCHEMY_CONN = conf.get("database", "SQL_ALCHEMY_CONN")

[2025-03-30T11:19:55.697+0000] {task_command.py:423} INFO - Running <TaskInstance: inout_data_ingestion.ingest_dummy_data scheduled__2024-10-07T03:00:00+00:00 [running]> on host ff9d64b065e6
[2025-03-30T11:19:55.737+0000] {taskinstance.py:2510} INFO - Exporting env vars: AIRFLOW_CTX_DAG_OWNER='***' AIRFLOW_CTX_DAG_ID='inout_data_ingestion' AIRFLOW_CTX_TASK_ID='ingest_dummy_data' AIRFLOW_CTX_EXECUTION_DATE='2024-10-07T03:00:00+00:00' AIRFLOW_CTX_TRY_NUMBER='1' AIRFLOW_CTX_DAG_RUN_ID='scheduled__2024-10-07T03:00:00+00:00'
[2025-03-30T11:19:55.740+0000] {inout_data.py:42} INFO - Successfully connected to MariaDB: INOUT on mariadb:3306
[2025-03-30T11:19:55.740+0000] {inout_data.py:63} ERROR - Error executing query: (1062, "Duplicate entry '2025-03-30 11:19:55-4349' for key 'PRIMARY'")
[2025-03-30T11:19:55.741+0000] {inout_data.py:63} ERROR - Error executing query: (1062, "Duplicate entry '2025-03-30 11:19:55-4349' for key 'PRIMARY'")
[2025-03-30T11:19:55.741+0000] {inout_data.py:63} ERROR - Error executing query: (1062, "Duplicate entry '2025-03-30 11:19:55-4349' for key 'PRIMARY'")
[2025-03-30T11:19:55.741+0000] {inout_data.py:63} ERROR - Error executing query: (1062, "Duplicate entry '2025-03-30 11:19:55-4349' for key 'PRIMARY'")
[2025-03-30T11:19:55.742+0000] {inout_data.py:63} ERROR - Error executing query: (1062, "Duplicate entry '2025-03-30 11:19:55-4349' for key 'PRIMARY'")
[2025-03-30T11:19:55.742+0000] {inout_data.py:63} ERROR - Error executing query: (1062, "Duplicate entry '2025-03-30 11:19:55-4349' for key 'PRIMARY'")
[2025-03-30T11:19:55.742+0000] {inout_data.py:63} ERROR - Error executing query: (1062, "Duplicate entry '2025-03-30 11:19:55-4349' for key 'PRIMARY'")
[2025-03-30T11:19:55.742+0000] {inout_data.py:63} ERROR - Error executing query: (1062, "Duplicate entry '2025-03-30 11:19:55-4349' for key 'PRIMARY'")
[2025-03-30T11:19:55.743+0000] {inout_data.py:63} ERROR - Error executing query: (1062, "Duplicate entry '2025-03-30 11:19:55-4349' for key 'PRIMARY'")
[2025-03-30T11:19:55.743+0000] {inout_data.py:63} ERROR - Error executing query: (1062, "Duplicate entry '2025-03-30 11:19:55-4349' for key 'PRIMARY'")
[2025-03-30T11:19:55.743+0000] {inout_data.py:63} ERROR - Error executing query: (1062, "Duplicate entry '2025-03-30 11:19:55-4349' for key 'PRIMARY'")
[2025-03-30T11:19:55.744+0000] {inout_data.py:63} ERROR - Error executing query: (1062, "Duplicate entry '2025-03-30 11:19:55-4349' for key 'PRIMARY'")
[2025-03-30T11:19:55.744+0000] {inout_data.py:152} INFO - Ingested 13 rows of dummy data.
[2025-03-30T11:19:55.744+0000] {inout_data.py:78} INFO - MariaDB connection closed.
[2025-03-30T11:19:55.744+0000] {python.py:202} INFO - Done. Returned value was: None
[2025-03-30T11:19:55.749+0000] {taskinstance.py:1149} INFO - Marking task as SUCCESS. dag_id=inout_data_ingestion, task_id=ingest_dummy_data, execution_date=20241007T030000, start_date=20250330T111955, end_date=20250330T111955
[2025-03-30T11:19:55.763+0000] {local_task_job_runner.py:234} INFO - Task exited with return code 0
[2025-03-30T11:19:55.776+0000] {taskinstance.py:3309} INFO - 0 downstream tasks scheduled from follow-on schedule check
