[2025-03-30T11:10:36.164+0000] {taskinstance.py:1979} INFO - Dependencies all met for dep_context=non-requeueable deps ti=<TaskInstance: inout_data_ingestion.create_table scheduled__2024-10-02T10:30:00+00:00 [queued]>
[2025-03-30T11:10:36.180+0000] {taskinstance.py:1979} INFO - Dependencies all met for dep_context=requeueable deps ti=<TaskInstance: inout_data_ingestion.create_table scheduled__2024-10-02T10:30:00+00:00 [queued]>
[2025-03-30T11:10:36.181+0000] {taskinstance.py:2193} INFO - Starting attempt 1 of 2
[2025-03-30T11:10:36.195+0000] {taskinstance.py:2214} INFO - Executing <Task(PythonOperator): create_table> on 2024-10-02 10:30:00+00:00
[2025-03-30T11:10:36.203+0000] {standard_task_runner.py:60} INFO - Started process 755 to run task
[2025-03-30T11:10:36.209+0000] {standard_task_runner.py:87} INFO - Running: ['***', 'tasks', 'run', 'inout_data_ingestion', 'create_table', 'scheduled__2024-10-02T10:30:00+00:00', '--job-id', '351', '--raw', '--subdir', 'DAGS_FOLDER/inout_data.py', '--cfg-path', '/tmp/tmpf9k9yh0p']
[2025-03-30T11:10:36.210+0000] {standard_task_runner.py:88} INFO - Job 351: Subtask create_table
[2025-03-30T11:10:36.227+0000] {warnings.py:109} WARNING - /home/***/.local/lib/python3.8/site-packages/***/settings.py:194: DeprecationWarning: The sql_alchemy_conn option in [core] has been moved to the sql_alchemy_conn option in [database] - the old setting has been used, but please update your config.
  SQL_ALCHEMY_CONN = conf.get("database", "SQL_ALCHEMY_CONN")

[2025-03-30T11:10:36.254+0000] {task_command.py:423} INFO - Running <TaskInstance: inout_data_ingestion.create_table scheduled__2024-10-02T10:30:00+00:00 [running]> on host ff9d64b065e6
[2025-03-30T11:10:36.321+0000] {taskinstance.py:2510} INFO - Exporting env vars: AIRFLOW_CTX_DAG_OWNER='***' AIRFLOW_CTX_DAG_ID='inout_data_ingestion' AIRFLOW_CTX_TASK_ID='create_table' AIRFLOW_CTX_EXECUTION_DATE='2024-10-02T10:30:00+00:00' AIRFLOW_CTX_TRY_NUMBER='1' AIRFLOW_CTX_DAG_RUN_ID='scheduled__2024-10-02T10:30:00+00:00'
[2025-03-30T11:10:36.328+0000] {inout_data.py:42} INFO - Successfully connected to MariaDB: INOUT on mariadb:3306
[2025-03-30T11:10:36.331+0000] {inout_data.py:124} INFO - Table emp_inout_rec created (if it didn't exist).
[2025-03-30T11:10:36.332+0000] {inout_data.py:78} INFO - MariaDB connection closed.
[2025-03-30T11:10:36.332+0000] {python.py:202} INFO - Done. Returned value was: None
[2025-03-30T11:10:36.340+0000] {taskinstance.py:1149} INFO - Marking task as SUCCESS. dag_id=inout_data_ingestion, task_id=create_table, execution_date=20241002T103000, start_date=20250330T111036, end_date=20250330T111036
[2025-03-30T11:10:36.396+0000] {local_task_job_runner.py:234} INFO - Task exited with return code 0
[2025-03-30T11:10:36.459+0000] {taskinstance.py:3309} INFO - 1 downstream tasks scheduled from follow-on schedule check
[2025-03-30T11:17:12.735+0000] {taskinstance.py:1979} INFO - Dependencies all met for dep_context=non-requeueable deps ti=<TaskInstance: inout_data_ingestion.create_table scheduled__2024-10-02T10:30:00+00:00 [queued]>
[2025-03-30T11:17:12.751+0000] {taskinstance.py:1979} INFO - Dependencies all met for dep_context=requeueable deps ti=<TaskInstance: inout_data_ingestion.create_table scheduled__2024-10-02T10:30:00+00:00 [queued]>
[2025-03-30T11:17:12.751+0000] {taskinstance.py:2193} INFO - Starting attempt 1 of 2
[2025-03-30T11:17:12.789+0000] {taskinstance.py:2214} INFO - Executing <Task(PythonOperator): create_table> on 2024-10-02 10:30:00+00:00
[2025-03-30T11:17:12.821+0000] {standard_task_runner.py:60} INFO - Started process 2609 to run task
[2025-03-30T11:17:12.842+0000] {standard_task_runner.py:87} INFO - Running: ['***', 'tasks', 'run', 'inout_data_ingestion', 'create_table', 'scheduled__2024-10-02T10:30:00+00:00', '--job-id', '1278', '--raw', '--subdir', 'DAGS_FOLDER/inout_data.py', '--cfg-path', '/tmp/tmp9x_2gn6p']
[2025-03-30T11:17:12.850+0000] {standard_task_runner.py:88} INFO - Job 1278: Subtask create_table
[2025-03-30T11:17:12.887+0000] {warnings.py:109} WARNING - /home/***/.local/lib/python3.8/site-packages/***/settings.py:194: DeprecationWarning: The sql_alchemy_conn option in [core] has been moved to the sql_alchemy_conn option in [database] - the old setting has been used, but please update your config.
  SQL_ALCHEMY_CONN = conf.get("database", "SQL_ALCHEMY_CONN")

[2025-03-30T11:17:12.957+0000] {task_command.py:423} INFO - Running <TaskInstance: inout_data_ingestion.create_table scheduled__2024-10-02T10:30:00+00:00 [running]> on host ff9d64b065e6
[2025-03-30T11:17:13.052+0000] {taskinstance.py:2510} INFO - Exporting env vars: AIRFLOW_CTX_DAG_OWNER='***' AIRFLOW_CTX_DAG_ID='inout_data_ingestion' AIRFLOW_CTX_TASK_ID='create_table' AIRFLOW_CTX_EXECUTION_DATE='2024-10-02T10:30:00+00:00' AIRFLOW_CTX_TRY_NUMBER='1' AIRFLOW_CTX_DAG_RUN_ID='scheduled__2024-10-02T10:30:00+00:00'
[2025-03-30T11:17:13.057+0000] {inout_data.py:42} INFO - Successfully connected to MariaDB: INOUT on mariadb:3306
[2025-03-30T11:17:13.059+0000] {inout_data.py:117} INFO - Table emp_inout_rec created (if it didn't exist).
[2025-03-30T11:17:13.059+0000] {inout_data.py:78} INFO - MariaDB connection closed.
[2025-03-30T11:17:13.060+0000] {python.py:202} INFO - Done. Returned value was: None
[2025-03-30T11:17:13.074+0000] {taskinstance.py:1149} INFO - Marking task as SUCCESS. dag_id=inout_data_ingestion, task_id=create_table, execution_date=20241002T103000, start_date=20250330T111712, end_date=20250330T111713
[2025-03-30T11:17:13.117+0000] {local_task_job_runner.py:234} INFO - Task exited with return code 0
[2025-03-30T11:17:13.151+0000] {taskinstance.py:3309} INFO - 0 downstream tasks scheduled from follow-on schedule check
[2025-03-30T11:29:39.325+0000] {taskinstance.py:1979} INFO - Dependencies all met for dep_context=non-requeueable deps ti=<TaskInstance: inout_data_ingestion.create_table scheduled__2024-10-02T10:30:00+00:00 [queued]>
[2025-03-30T11:29:39.338+0000] {taskinstance.py:1979} INFO - Dependencies all met for dep_context=requeueable deps ti=<TaskInstance: inout_data_ingestion.create_table scheduled__2024-10-02T10:30:00+00:00 [queued]>
[2025-03-30T11:29:39.340+0000] {taskinstance.py:2193} INFO - Starting attempt 1 of 2
[2025-03-30T11:29:39.364+0000] {taskinstance.py:2214} INFO - Executing <Task(PythonOperator): create_table> on 2024-10-02 10:30:00+00:00
[2025-03-30T11:29:39.368+0000] {standard_task_runner.py:60} INFO - Started process 4531 to run task
[2025-03-30T11:29:39.375+0000] {standard_task_runner.py:87} INFO - Running: ['***', 'tasks', 'run', 'inout_data_ingestion', 'create_table', 'scheduled__2024-10-02T10:30:00+00:00', '--job-id', '2240', '--raw', '--subdir', 'DAGS_FOLDER/inout_data.py', '--cfg-path', '/tmp/tmpkpqhfqlo']
[2025-03-30T11:29:39.378+0000] {standard_task_runner.py:88} INFO - Job 2240: Subtask create_table
[2025-03-30T11:29:39.394+0000] {warnings.py:109} WARNING - /home/***/.local/lib/python3.8/site-packages/***/settings.py:194: DeprecationWarning: The sql_alchemy_conn option in [core] has been moved to the sql_alchemy_conn option in [database] - the old setting has been used, but please update your config.
  SQL_ALCHEMY_CONN = conf.get("database", "SQL_ALCHEMY_CONN")

[2025-03-30T11:29:39.438+0000] {task_command.py:423} INFO - Running <TaskInstance: inout_data_ingestion.create_table scheduled__2024-10-02T10:30:00+00:00 [running]> on host ff9d64b065e6
[2025-03-30T11:29:39.519+0000] {taskinstance.py:2510} INFO - Exporting env vars: AIRFLOW_CTX_DAG_OWNER='***' AIRFLOW_CTX_DAG_ID='inout_data_ingestion' AIRFLOW_CTX_TASK_ID='create_table' AIRFLOW_CTX_EXECUTION_DATE='2024-10-02T10:30:00+00:00' AIRFLOW_CTX_TRY_NUMBER='1' AIRFLOW_CTX_DAG_RUN_ID='scheduled__2024-10-02T10:30:00+00:00'
[2025-03-30T11:29:39.525+0000] {logging_mixin.py:188} INFO - Successfully connected to MariaDB: INOUT on mariadb:3306
[2025-03-30T11:29:39.526+0000] {inout_data.py:46} INFO - Table emp_inout_rec created (if it didn't exist).
[2025-03-30T11:29:39.527+0000] {logging_mixin.py:188} INFO - MariaDB connection closed.
[2025-03-30T11:29:39.527+0000] {python.py:202} INFO - Done. Returned value was: None
[2025-03-30T11:29:39.535+0000] {taskinstance.py:1149} INFO - Marking task as SUCCESS. dag_id=inout_data_ingestion, task_id=create_table, execution_date=20241002T103000, start_date=20250330T112939, end_date=20250330T112939
[2025-03-30T11:29:39.555+0000] {local_task_job_runner.py:234} INFO - Task exited with return code 0
[2025-03-30T11:29:39.575+0000] {taskinstance.py:3309} INFO - 1 downstream tasks scheduled from follow-on schedule check
[2025-03-30T11:34:33.276+0000] {taskinstance.py:1979} INFO - Dependencies all met for dep_context=non-requeueable deps ti=<TaskInstance: inout_data_ingestion.create_table scheduled__2024-10-02T10:30:00+00:00 [queued]>
[2025-03-30T11:34:33.292+0000] {taskinstance.py:1979} INFO - Dependencies all met for dep_context=requeueable deps ti=<TaskInstance: inout_data_ingestion.create_table scheduled__2024-10-02T10:30:00+00:00 [queued]>
[2025-03-30T11:34:33.293+0000] {taskinstance.py:2193} INFO - Starting attempt 1 of 2
[2025-03-30T11:34:33.330+0000] {taskinstance.py:2214} INFO - Executing <Task(PythonOperator): create_table> on 2024-10-02 10:30:00+00:00
[2025-03-30T11:34:33.341+0000] {standard_task_runner.py:60} INFO - Started process 5982 to run task
[2025-03-30T11:34:33.346+0000] {standard_task_runner.py:87} INFO - Running: ['***', 'tasks', 'run', 'inout_data_ingestion', 'create_table', 'scheduled__2024-10-02T10:30:00+00:00', '--job-id', '2964', '--raw', '--subdir', 'DAGS_FOLDER/inout_data.py', '--cfg-path', '/tmp/tmpo4ogdfv7']
[2025-03-30T11:34:33.349+0000] {standard_task_runner.py:88} INFO - Job 2964: Subtask create_table
[2025-03-30T11:34:33.379+0000] {warnings.py:109} WARNING - /home/***/.local/lib/python3.8/site-packages/***/settings.py:194: DeprecationWarning: The sql_alchemy_conn option in [core] has been moved to the sql_alchemy_conn option in [database] - the old setting has been used, but please update your config.
  SQL_ALCHEMY_CONN = conf.get("database", "SQL_ALCHEMY_CONN")

[2025-03-30T11:34:33.438+0000] {task_command.py:423} INFO - Running <TaskInstance: inout_data_ingestion.create_table scheduled__2024-10-02T10:30:00+00:00 [running]> on host ff9d64b065e6
[2025-03-30T11:34:33.572+0000] {taskinstance.py:2510} INFO - Exporting env vars: AIRFLOW_CTX_DAG_OWNER='***' AIRFLOW_CTX_DAG_ID='inout_data_ingestion' AIRFLOW_CTX_TASK_ID='create_table' AIRFLOW_CTX_EXECUTION_DATE='2024-10-02T10:30:00+00:00' AIRFLOW_CTX_TRY_NUMBER='1' AIRFLOW_CTX_DAG_RUN_ID='scheduled__2024-10-02T10:30:00+00:00'
[2025-03-30T11:34:33.580+0000] {logging_mixin.py:188} INFO - Successfully connected to MariaDB: INOUT on mariadb:3306
[2025-03-30T11:34:33.582+0000] {inout_data.py:46} INFO - Table emp_inout_rec created (if it didn't exist).
[2025-03-30T11:34:33.584+0000] {logging_mixin.py:188} INFO - MariaDB connection closed.
[2025-03-30T11:34:33.585+0000] {python.py:202} INFO - Done. Returned value was: None
[2025-03-30T11:34:33.598+0000] {taskinstance.py:1149} INFO - Marking task as SUCCESS. dag_id=inout_data_ingestion, task_id=create_table, execution_date=20241002T103000, start_date=20250330T113433, end_date=20250330T113433
[2025-03-30T11:34:33.663+0000] {local_task_job_runner.py:234} INFO - Task exited with return code 0
[2025-03-30T11:34:33.693+0000] {taskinstance.py:3309} INFO - 1 downstream tasks scheduled from follow-on schedule check
[2025-03-30T11:42:17.380+0000] {taskinstance.py:1979} INFO - Dependencies all met for dep_context=non-requeueable deps ti=<TaskInstance: inout_data_ingestion.create_table scheduled__2024-10-02T10:30:00+00:00 [queued]>
[2025-03-30T11:42:17.390+0000] {taskinstance.py:1979} INFO - Dependencies all met for dep_context=requeueable deps ti=<TaskInstance: inout_data_ingestion.create_table scheduled__2024-10-02T10:30:00+00:00 [queued]>
[2025-03-30T11:42:17.391+0000] {taskinstance.py:2193} INFO - Starting attempt 1 of 2
[2025-03-30T11:42:17.406+0000] {taskinstance.py:2214} INFO - Executing <Task(PythonOperator): create_table> on 2024-10-02 10:30:00+00:00
[2025-03-30T11:42:17.413+0000] {standard_task_runner.py:60} INFO - Started process 7324 to run task
[2025-03-30T11:42:17.416+0000] {standard_task_runner.py:87} INFO - Running: ['***', 'tasks', 'run', 'inout_data_ingestion', 'create_table', 'scheduled__2024-10-02T10:30:00+00:00', '--job-id', '3637', '--raw', '--subdir', 'DAGS_FOLDER/inout_data.py', '--cfg-path', '/tmp/tmp7880t5az']
[2025-03-30T11:42:17.417+0000] {standard_task_runner.py:88} INFO - Job 3637: Subtask create_table
[2025-03-30T11:42:17.424+0000] {warnings.py:109} WARNING - /home/***/.local/lib/python3.8/site-packages/***/settings.py:194: DeprecationWarning: The sql_alchemy_conn option in [core] has been moved to the sql_alchemy_conn option in [database] - the old setting has been used, but please update your config.
  SQL_ALCHEMY_CONN = conf.get("database", "SQL_ALCHEMY_CONN")

[2025-03-30T11:42:17.444+0000] {task_command.py:423} INFO - Running <TaskInstance: inout_data_ingestion.create_table scheduled__2024-10-02T10:30:00+00:00 [running]> on host ff9d64b065e6
[2025-03-30T11:42:17.555+0000] {taskinstance.py:2510} INFO - Exporting env vars: AIRFLOW_CTX_DAG_OWNER='***' AIRFLOW_CTX_DAG_ID='inout_data_ingestion' AIRFLOW_CTX_TASK_ID='create_table' AIRFLOW_CTX_EXECUTION_DATE='2024-10-02T10:30:00+00:00' AIRFLOW_CTX_TRY_NUMBER='1' AIRFLOW_CTX_DAG_RUN_ID='scheduled__2024-10-02T10:30:00+00:00'
[2025-03-30T11:42:17.558+0000] {taskinstance.py:2728} ERROR - Task failed with exception
Traceback (most recent call last):
  File "/home/airflow/.local/lib/python3.8/site-packages/airflow/models/taskinstance.py", line 444, in _execute_task
    result = _execute_callable(context=context, **execute_callable_kwargs)
  File "/home/airflow/.local/lib/python3.8/site-packages/airflow/models/taskinstance.py", line 414, in _execute_callable
    return execute_callable(context=context, **execute_callable_kwargs)
  File "/home/airflow/.local/lib/python3.8/site-packages/airflow/operators/python.py", line 200, in execute
    return_value = self.execute_callable()
  File "/home/airflow/.local/lib/python3.8/site-packages/airflow/operators/python.py", line 217, in execute_callable
    return self.python_callable(*self.op_args, **self.op_kwargs)
  File "/opt/airflow/dags/inout_data.py", line 26, in create_table_if_not_exists
    dao = MariaDBDAO(CONFIG_FILE, CONN_ID)
TypeError: MariaDBDAO() takes no arguments
[2025-03-30T11:42:17.568+0000] {taskinstance.py:1149} INFO - Marking task as UP_FOR_RETRY. dag_id=inout_data_ingestion, task_id=create_table, execution_date=20241002T103000, start_date=20250330T114217, end_date=20250330T114217
[2025-03-30T11:42:17.578+0000] {standard_task_runner.py:107} ERROR - Failed to execute job 3637 for task create_table (MariaDBDAO() takes no arguments; 7324)
[2025-03-30T11:42:17.596+0000] {local_task_job_runner.py:234} INFO - Task exited with return code 1
[2025-03-30T11:42:17.620+0000] {taskinstance.py:3309} INFO - 0 downstream tasks scheduled from follow-on schedule check
